Workbook

Sheet Race_Dashboard
A1: Race Name | B1: Circuit Type | C1: Location | D1: Weather Forecast | E1: Tier 1 Pick | F1: Tier 2 Pick | G1: Tier 3 Pick | H1: Tier 4 Pick | I1: Tier 5 Pick | J1: Tier 6 Pick
A2: Mock Race on Presto | B2: Street Course | E2: Scott McLaughlin | F2: Kyle Kirkwood | G2: Marcus Armstrong | H2: Rinus VeeKay | I2: Louis Foster | J2: Caio Collet (R)
A3: =Race_Schedule!A2 -> Firestone Grand Prix of St. Petersburg | B3: Street Course | C3: St Petersburg, FL | D3: =GET_WEATHER(C3) -> 52°F, 0% Rain | E3: Alex Palou | F3: Marcus Ericsson | G3: Romain Grosjean | H3: Dennis Hauger (R) | I3: Graham Rahal | J3: Mick Schumacher (R)
A4: =Race_Schedule!A3 -> Good Ranchers 250 | B4: Oval | C4: Avondale, AZ | D4: =GET_WEATHER(C4) -> 98°F, 0% Rain | E4: David Malukas | F4: Scott Dixon | G4: Mick Schumacher (R) | H4: Felix Rosenqvist | I4: Louis Foster | J4: Sting Ray Robb
A5: =Race_Schedule!A4 -> Java House Grand Prix of Arlington | B5: Street Course | C5: Arlington, TX | D5: =GET_WEATHER(C5) -> 79°F, 0% Rain
A6: =Race_Schedule!A5 -> Children's of Alabama Indy Grand Prix | B6: Road Course | C6: Birmingham, AL | D6: =GET_WEATHER(C6) -> 55°F, 0% Rain
A7: =Race_Schedule!A6 -> Acura Grand Prix of Long Beach | B7: Road Course | C7: Long Beach, CA | D7: =GET_WEATHER(C7) -> 69°F, 0% Rain
A8: =Race_Schedule!A7 -> Sonsio Grand Prix (IMS Road Course) | B8: Road Course | C8: Speedway, IN | D8: =GET_WEATHER(C8) -> 44°F, 16% Rain
A9: =Race_Schedule!A8 -> The 110th Indianapolis 500 | B9: Oval | C9: Speedway, IN | D9: =GET_WEATHER(C9) -> 44°F, 16% Rain
A10: =Race_Schedule!A9 -> Chevrolet Detroit Grand Prix | B10: Street Course | C10: Detroit, MI | D10: =GET_WEATHER(C10) -> 38°F, 15% Rain
A11: =Race_Schedule!A10 -> Bommarito Automotive Group 500 | B11: Oval | C11: Madison, IL | D11: =GET_WEATHER(C11) -> 44°F, 0% Rain
A12: =Race_Schedule!A11 -> XPEL Grand Prix at Road America | B12: Road Course | C12: Elkhart Lake, WI | D12: =GET_WEATHER(C12) -> 36°F, 0% Rain
A13: =Race_Schedule!A12 -> Honda Indy 200 at Mid-Ohio | B13: Road Course | C13: Lexington, OH | D13: =GET_WEATHER(C13) -> 74°F, 61% Rain
A14: =Race_Schedule!A13 -> Borchetta Bourbon Music City Grand Prix | B14: Oval | C14: Lebanon, TN | D14: =GET_WEATHER(C14) -> 50°F, 100% Rain
A15: =Race_Schedule!A14 -> BITNILE.com Grand Prix of Portland | B15: Road Course | C15: Portland, OR | D15: =GET_WEATHER(C15) -> 55°F, 9% Rain
A16: =Race_Schedule!A15 -> Ontario Honda Dealers Indy at Markham | B16: Street Course | C16: Markham, ON | D16: =GET_WEATHER(C16) -> 35°F, 20% Rain
... A20: =Race_Schedule!A19 -> IndyCar Grand Prix of Monterey (Laguna Seca) | B20: Road Course | C20: Monterey, CA | D20: =GET_WEATHER(C20) -> 61°F, 68% Rain
A21: =Race_Schedule!A20

Sheet Driver_Stats
A1: Driver Name | B1: Current Tier | C1: Avg Finish (Last 5) | D1: Oval Rating | E1: Road Rating | F1: Street Rating | G1: Tier Value Score
A2: Alex Palou | B2: 1 | G2: =B2 - C2 -> 1
A3: Scott Dixon | B3: 3 | G3: =B3 - C3 -> 3
A4: Kyffin Simpson | B4: 4 | G4: =B4 - C4 -> 4
A5: Will Power | B5: 3 | G5: =B5 - C5 -> 3
A6: Kyle Kirkwood | B6: 3 | G6: =B6 - C6 -> 3
A7: Marcus Ericsson | B7: 2 | G7: =B7 - C7 -> 2
A8: Josef Newgarden | B8: 3 | G8: =B8 - C8 -> 3
A9: Scott McLaughlin | B9: 1 | G9: =B9 - C9 -> 1
A10: David Malukas | B10: 1 | G10: =B10 - C10 -> 1
A11: Pato O'Ward | B11: 1 | G11: =B11 - C11 -> 1
A12: Christian Lundgaard | B12: 2 | G12: =B12 - C12 -> 2
A13: Nolan Siegel | B13: 5 | G13: =B13 - C13 -> 5
... A26: Dennis Hauger (R) | B26: 4 | G26: =B26 - C26 -> 4
G27: =B27 - C27 -> 0
G28: =B28 - C28 -> 0
G29: =B29 - C29 -> 0
G30: =B30 - C30 -> 0
G31: =B31 - C31 -> 0
G32: =B32 - C32 -> 0
G33: =B33 - C33 -> 0
G34: =B34 - C34 -> 0
G35: =B35 - C35 -> 0
G36: =B36 - C36 -> 0
G37: =B37 - C37 -> 0
G38: =B38 - C38 -> 0
... G120: =B120 - C120 -> 0

Sheet Race_Schedule
A1: Race Name | B1: Date | C1: Location | D1: Circuit Type
A2: Firestone Grand Prix of St. Petersburg | B2: 46082 | C2: St. Petersburg, FL, USA | D2: Street
A3: Good Ranchers 250 | B3: 46088 | C3: Avondale, AZ, USA | D3: Oval
A4: Java House Grand Prix of Arlington | B4: 46096 | C4: Arlington, TX, USA | D4: Street
A5: Children's of Alabama Indy Grand Prix | B5: 46110 | C5: Birmingham, AL, USA | D5: Road
A6: Acura Grand Prix of Long Beach | B6: 46131 | C6: Long Beach, CA, USA | D6: Street
A7: Sonsio Grand Prix (IMS Road Course) | B7: 46151 | C7: Speedway, IN, USA | D7: Road
A8: The 110th Indianapolis 500 | B8: 46166 | C8: Speedway, IN, USA | D8: Oval
A9: Chevrolet Detroit Grand Prix | B9: 46173 | C9: Detroit, MI, USA | D9: Street
A10: Bommarito Automotive Group 500 | B10: 46180 | C10: Madison, IL, USA | D10: Oval
A11: XPEL Grand Prix at Road America | B11: 46194 | C11: Elkhart Lake, WI, USA | D11: Road
A12: Honda Indy 200 at Mid-Ohio | B12: 46208 | C12: Lexington, OH, USA | D12: Road
A13: Borchetta Bourbon Music City Grand Prix | B13: 46222 | C13: Lebanon, TN, USA | D13: Oval
... A19: IndyCar Grand Prix of Monterey (Laguna Seca) | B19: 46271 | C19: Monterey, CA, USA | D19: Road

Sheet Driver_List
A1: Driver Name | B1: Team | C1: Car # | D1: Engine | E1: Status
A2: Alex Palou | B2: Chip Ganassi Racing | C2: 10 | D2: Honda | E2: Full-time
A3: Scott Dixon | B3: Chip Ganassi Racing | C3: 9 | D3: Honda | E3: Full-time
A4: Kyffin Simpson | B4: Chip Ganassi Racing | C4: 8 | D4: Honda | E4: Full-time
A5: Will Power | B5: Andretti Global | C5: 26 | D5: Honda | E5: Full-time
A6: Kyle Kirkwood | B6: Andretti Global | C6: 27 | D6: Honda | E6: Full-time
A7: Marcus Ericsson | B7: Andretti Global | C7: 28 | D7: Honda | E7: Full-time
A8: Josef Newgarden | B8: Team Penske | C8: 2 | D8: Chevrolet | E8: Full-time
A9: Scott McLaughlin | B9: Team Penske | C9: 3 | D9: Chevrolet | E9: Full-time
A10: David Malukas | B10: Team Penske | C10: 12 | D10: Chevrolet | E10: Full-time
A11: Pato O'Ward | B11: Arrow McLaren | C11: 5 | D11: Chevrolet | E11: Full-time
A12: Christian Lundgaard | B12: Arrow McLaren | C12: 7 | D12: Chevrolet | E12: Full-time
A13: Nolan Siegel | B13: Arrow McLaren | C13: 6 | D13: Chevrolet | E13: Full-time
... A26: Dennis Hauger (R) | B26: Dale Coyne Racing | C26: 19 | D26: Honda | E26: Full-time

Sheet Race_Results
A1: Race | B1: Driver | C1: Weekly Tier | D1: Finish Position | E1: Points Earned | F1: Weekly Total | G1: Season Total
A2: St. Petersburg | B2: =Race_Dashboard!E3 -> Alex Palou | C2: =Tier_History!C2 -> 1 | D2: 1 | E2: =D2 -> 1 | F2: =SUM(E2:E7) -> 68 | G2: =SUM(E2:E113) -> 152
B3: =Race_Dashboard!F3 -> Marcus Ericsson | C3: =Tier_History!C3 -> 2 | D3: 6 | E3: =D3 -> 6
B4: =Race_Dashboard!G3 -> Romain Grosjean | C4: =Tier_History!C4 -> 3 | D4: 8 | E4: =D4 -> 8
B5: =Race_Dashboard!H3 -> Dennis Hauger (R) | C5: =Tier_History!C5 -> 4 | D5: 10 | E5: =D5 -> 10
B6: =Race_Dashboard!I3 -> Graham Rahal | C6: =Tier_History!C6 -> 5 | D6: 18 | E6: =D6 -> 18
B7: =Race_Dashboard!J3 -> Mick Schumacher (R) | C7: =Tier_History!C7 -> 6 | D7: 25 | E7: =D7 -> 25
A8: Pheonix | B8: David Malukas | C8: 1 | D8: 3 | E8: =D8 -> 3 | F8: =SUM(E8:E13) -> 84
B9: Scott Dixon | C9: 2 | D9: 7 | E9: =D9 -> 7
B10: Mick Schumacher (R) | C10: 3 | D10: 18 | E10: =D10 -> 18
B11: Felix Rosenqvist | C11: 4 | D11: 12 | E11: =D11 -> 12
B12: Louis Foster | C12: 5 | D12: 23 | E12: =D12 -> 23
B13: Sting Ray Robb | C13: 6 | D13: 21 | E13: =D13 -> 21
A14: Arlington | E14: =D14 | F14: =SUM(E14:E19) -> 0
E15: =D15
E16: =D16
E17: =D17
E18: =D18
E19: =D19
A20: Barber | E20: =D20 | F20: =SUM(E20:E25) -> 0
E21: =D21
E22: =D22
E23: =D23
E24: =D24
E25: =D25
A26: Long Beach | E26: =D26 | F26: =SUM(E26:E31) -> 0
E27: =D27
E28: =D28
E29: =D29
E30: =D30
E31: =D31
A32: Indy Road | E32: =D32 | F32: =SUM(E32:E37) -> 0
E33: =D33
E34: =D34
E35: =D35
E36: =D36
E37: =D37
A38: Indy 500 | E38: =D38 | F38: =SUM(E38:E43) -> 0
E39: =D39
E40: =D40
...

Sheet Tier_History
A1: Race Name | B1: Driver Name | C1: Assigned Tier | D1: Finishing Position | E1: Tier Delta
A2: St. Petersburg | B2: Alex Palou | C2: 1
A3: St. Petersburg | B3: Marcus Ericsson | C3: 2
A4: St. Petersburg | B4: Romain Grosjean | C4: 3
A5: St. Petersburg | B5: Dennis Hauger (R) | C5: 4
A6: St. Petersburg | B6: Graham Rahal | C6: 5
A7: St. Petersburg | B7: Mick Schumacher (R) | C7: 6

Sheet Practice_Results
A1: Rank | B1: Car | C1: Driver Name | D1: Best Time | E1: Speed (MPH) | F1: Total Laps
A2: 1 | B2: 3 | C2: McLaughlin, Scott | D2: 01:01.1020 | E2: 106.052 | F2: 43
A3: 2 | B3: 60 | C3: Rosenqvist, Felix | D3: 01:01.1660 | E3: 105.941 | F3: 42
A4: 3 | B4: 27 | C4: Kirkwood, Kyle | D4: 01:01.1777 | E4: 105.921 | F4: 44
A5: 4 | B5: 8 | C5: Simpson, Kyffin | D5: 01:01.1782 | E5: 105.92 | F5: 42
A6: 5 | B6: 28 | C6: Ericsson, Marcus | D6: 01:01.1967 | E6: 105.888 | F6: 43
A7: 6 | B7: 10 | C7: Palou, Alex | D7: 01:01.2614 | E7: 105.776 | F7: 37
A8: 7 | B8: 66 | C8: Armstrong, Marcus | D8: 01:01.3035 | E8: 105.704 | F8: 45
A9: 8 | B9: 21 | C9: Rasmussen, Christian | D9: 01:01.4828 | E9: 105.395 | F9: 34
A10: 9 | B10: 12 | C10: Malukas, David | D10: 01:01.4870 | E10: 105.388 | F10: 47
A11: 10 | B11: 7 | C11: Lundgaard, Christian | D11: 01:01.5235 | E11: 105.326 | F11: 33
A12: 11 | B12: 76 | C12: VeeKay, Rinus | D12: 01:01.5444 | E12: 105.29 | F12: 40
A13: 12 | B13: 5 | C13: O'Ward, Pato | D13: 01:01.5754 | E13: 105.237 | F13: 43
... A26: 25 | B26: 4 | C26: Collet, Caio (R) | D26: 01:02.2576 | E26: 104.084 | F26: 41

Sheet Qualifying_Results
A1: St. Petersburg
A2: Rank | B2: Car | C2: Driver Name | D2: Time | E2: Speed (MPH) | F2: Session
A3: 1 | B3: 3 | C3: McLaughlin, Scott | D3: 01:00.5426 | E3: 107.032 | F3: Round 3 / Firestone Fast Six
A4: 2 | B4: 28 | C4: Ericsson, Marcus | D4: 01:00.5621 | E4: 106.998 | F4: Round 3 / Firestone Fast Six
A5: 3 | B5: 19 | C5: Hauger, Dennis (R) | D5: 01:00.5743 | E5: 106.976 | F5: Round 3 / Firestone Fast Six
A6: 4 | B6: 10 | C6: Palou, Alex | D6: 01:00.6842 | E6: 106.782 | F6: Round 3 / Firestone Fast Six
A7: 5 | B7: 12 | C7: Malukas, David | D7: 01:00.7638 | E7: 106.642 | F7: Round 3 / Firestone Fast Six
A8: 6 | B8: 18 | C8: Grosjean, Romain | D8: 01:01.3462 | E8: 105.63 | F8: Round 3 / Firestone Fast Six
A9: 7 | B9: 66 | C9: Armstrong, Marcus | D9: 01:00.7820 | E9: 106.611 | F9: Elimination Round 2 / Top 12
A10: 8 | B10: 5 | C10: O'Ward, Pato | D10: 01:00.8863 | E10: 106.428 | F10: Elimination Round 2 / Top 12
A11: 9 | B11: 45 | C11: Foster, Louis | D11: 01:00.9472 | E11: 106.322 | F11: Elimination Round 2 / Top 12
A12: 10 | B12: 8 | C12: Simpson, Kyffin | D12: 01:00.9811 | E12: 106.262 | F12: Elimination Round 2 / Top 12
A13: 11 | B13: 60 | C13: Rosenqvist, Felix | D13: 01:00.9840 | E13: 106.257 | F13: Elimination Round 2 / Top 12
A14: 12 | B14: 7 | C14: Lundgaard, Christian | D14: 01:00.9842 | E14: 106.257 | F14: Elimination Round 2 / Top 12
... A27: 25 | B27: 20 | C27: Rossi, Alexander | D27: 01:01.6031 | E27: 105.19 | F27: Elimination Round 1 / Group 2
A29: Phoenix
A30: Rank | B30: Car | C30: Driver Name | D30: Team | E30: Time (2 Laps) | F30: Avg. Speed (MPH)
A31: 1 | B31: 12 | C31: David Malukas | D31: Team Penske | E31: 00:41.0530 | F31: 175.383
A32: 2 | B32: 2 | C32: Josef Newgarden | D32: Team Penske | E32: 00:41.2493 | F32: 174.548
A33: 3 | B33: 15 | C33: Graham Rahal | D33: Rahal Letterman Lanigan Racing | E33: 00:41.3810 | F33: 173.993
A34: 4 | B34: 47 | C34: Mick Schumacher | D34: Rahal Letterman Lanigan Racing | E34: 00:41.4587 | F34: 173.667
A35: 5 | B35: 3 | C35: Scott McLaughlin | D35: Team Penske | E35: 00:41.5109 | F35: 173.448
A36: 6 | B36: 20 | C36: Alexander Rossi | D36: Ed Carpenter Racing | E36: 00:41.5252 | F36: 173.389
A37: 7 | B37: 5 | C37: Pato O'Ward | D37: Arrow McLaren | E37: 00:41.5359 | F37: 173.344
A38: 8 | B38: 76 | C38: Rinus VeeKay | D38: Juncos Hollinger Racing | E38: 00:41.5589 | F38: 173.248
A39: 9 | B39: 6 | C39: Nolan Siegel | D39: Arrow McLaren | E39: 00:41.6322 | F39: 172.943
A40: 10 | B40: 10 | C40: Alex Palou | D40: Chip Ganassi Racing | E40: 00:41.6454 | F40: 172.888
A41: 11 | B41: 27 | C41: Kyle Kirkwood | D41: Andretti Global | E41: 00:41.6478 | F41: 172.878
A42: 12 | B42: 77 | C42: Sting Ray Robb | D42: Juncos Hollinger Racing | E42: 00:41.6821 | F42: 172.536
... A46: 16 | B46: 45 | C46: Louis Foster | D46: Rahal Letterman Lanigan Racing | E46: 00:41.8120 | F46: 171.8
A47: 25 | B47: 26 | C47: Will Power | D47: Andretti Global | E47: DNF | F47: 174.137*
A48: DNS | B48: 60 | C48: Felix Rosenqvist | D48: Meyer Shank Racing | E48: N/A | F48: N/A

Sheet Beta_Dashboard
A1: Race Name | B1: Circuit Type | C1: Location | D1: Weather Forecast | E1: T1 Pick | F1: T1 Pts | G1: T2 Pick | H1: T2 Pts | I1: T3 Pick | J1: T3 Pts | K1: T4 Pick | L1: T4 Pts | M1: T5 Pick | N1: T5 Pts | O1: T6 Pick | P1: T6 Pts | Q1: WEEKLY TOTAL
A2: St. Petersburg | B2: Street Course | C2: St. Petersburg, FL | R2: 0
A3: Arlington GP | B3: Street Course | C3: Arlington, TX | R3: 0
A4: Long Beach | B4: Street Course | C4: Long Beach, CA | R4: 0
A5: Indy 500 | B5: Oval | C5: Speedway, IN | R5: 0
A6: Freedom 250 | B6: Street Course | C6: Washington DC | R6: 0
